mkdir: cannot create directory ‘/home/wesley/EDC/FPC/ML/HyperOpt//Heatflux/0607_V2’: No such file or directory
==========================================================
Starting on : Mon Jun  7 10:36:09 CST 2021
Running on node : centos77-c6
Current directory : /home/wesley/EDC/FPC/ML/Heatflux
Current job ID : 552597.centos77-h1
==========================================================
tee: 0607_V2/hf1.log: No such file or directory
2021-06-07 10:36:11.526505: W tensorflow/stream_executor/platform/default/dso_loader.cc:60] Could not load dynamic library 'libcudart.so.11.0'; dlerror: libcudart.so.11.0: cannot open shared object file: No such file or directory; LD_LIBRARY_PATH: /opt/intel-2020U1/compilers_and_libraries_2020.1.217/linux/compiler/lib/intel64_lin:/opt/intel-2020U1/compilers_and_libraries_2020.1.217/linux/mpi/intel64/libfabric/lib:/opt/intel-2020U1/compilers_and_libraries_2020.1.217/linux/mpi/intel64/lib/release:/opt/intel-2020U1/compilers_and_libraries_2020.1.217/linux/mpi/intel64/lib:/opt/intel-2020U1/compilers_and_libraries_2020.1.217/linux/ipp/lib/intel64:/opt/intel-2020U1/compilers_and_libraries_2020.1.217/linux/compiler/lib/intel64_lin:/opt/intel-2020U1/compilers_and_libraries_2020.1.217/linux/mkl/lib/intel64_lin:/opt/intel-2020U1/compilers_and_libraries_2020.1.217/linux/tbb/lib/intel64/gcc4.8:/opt/intel-2020U1/compilers_and_libraries_2020.1.217/linux/tbb/lib/intel64/gcc4.8:/opt/intel-2020U1/debugger_2020/python/intel64/lib:/opt/intel-2020U1/debugger_2020/libipt/intel64/lib:/opt/intel-2020U1/compilers_and_libraries_2020.1.217/linux/daal/lib/intel64_lin:/opt/intel-2020U1/compilers_and_libraries_2020.1.217/linux/daal/../tbb/lib/intel64_lin/gcc4.4:/opt/intel-2020U1/compilers_and_libraries_2020.1.217/linux/daal/../tbb/lib/intel64_lin/gcc4.8:/opt/intel-2020U1/parallel_studio_xe_2020.1.102/compilers_and_libraries_2020/linux/../../tbb/lib/intel64_lin:/opt/intel-2020U1/parallel_studio_xe_2020.1.102/compilers_and_libraries_2020/linux/../../compiler/lib/intel64_lin:/opt/intel-2020U1/parallel_studio_xe_2020.1.102/compilers_and_libraries_2020/linux/../../mkl/lib/intel64_lin:/home/wesley/anaconda3/lib/
2021-06-07 10:36:11.526547: I tensorflow/stream_executor/cuda/cudart_stub.cc:29] Ignore above cudart dlerror if you do not have a GPU set up on your machine.
delta_T:[8.]
hf_onj:19405.97369810055
Tubes 1:
[350.0, array([358.])]
2021-06-07 10:36:15.349912: I tensorflow/compiler/jit/xla_cpu_device.cc:41] Not creating XLA devices, tf_xla_enable_xla_devices not set
2021-06-07 10:36:15.350891: W tensorflow/stream_executor/platform/default/dso_loader.cc:60] Could not load dynamic library 'libcuda.so.1'; dlerror: libcuda.so.1: cannot open shared object file: No such file or directory; LD_LIBRARY_PATH: /opt/intel-2020U1/compilers_and_libraries_2020.1.217/linux/compiler/lib/intel64_lin:/opt/intel-2020U1/compilers_and_libraries_2020.1.217/linux/mpi/intel64/libfabric/lib:/opt/intel-2020U1/compilers_and_libraries_2020.1.217/linux/mpi/intel64/lib/release:/opt/intel-2020U1/compilers_and_libraries_2020.1.217/linux/mpi/intel64/lib:/opt/intel-2020U1/compilers_and_libraries_2020.1.217/linux/ipp/lib/intel64:/opt/intel-2020U1/compilers_and_libraries_2020.1.217/linux/compiler/lib/intel64_lin:/opt/intel-2020U1/compilers_and_libraries_2020.1.217/linux/mkl/lib/intel64_lin:/opt/intel-2020U1/compilers_and_libraries_2020.1.217/linux/tbb/lib/intel64/gcc4.8:/opt/intel-2020U1/compilers_and_libraries_2020.1.217/linux/tbb/lib/intel64/gcc4.8:/opt/intel-2020U1/debugger_2020/python/intel64/lib:/opt/intel-2020U1/debugger_2020/libipt/intel64/lib:/opt/intel-2020U1/compilers_and_libraries_2020.1.217/linux/daal/lib/intel64_lin:/opt/intel-2020U1/compilers_and_libraries_2020.1.217/linux/daal/../tbb/lib/intel64_lin/gcc4.4:/opt/intel-2020U1/compilers_and_libraries_2020.1.217/linux/daal/../tbb/lib/intel64_lin/gcc4.8:/opt/intel-2020U1/parallel_studio_xe_2020.1.102/compilers_and_libraries_2020/linux/../../tbb/lib/intel64_lin:/opt/intel-2020U1/parallel_studio_xe_2020.1.102/compilers_and_libraries_2020/linux/../../compiler/lib/intel64_lin:/opt/intel-2020U1/parallel_studio_xe_2020.1.102/compilers_and_libraries_2020/linux/../../mkl/lib/intel64_lin:/home/wesley/anaconda3/lib/
2021-06-07 10:36:15.350921: W tensorflow/stream_executor/cuda/cuda_driver.cc:326] failed call to cuInit: UNKNOWN ERROR (303)
2021-06-07 10:36:15.350947: I tensorflow/stream_executor/cuda/cuda_diagnostics.cc:156] kernel driver does not appear to be running on this host (centos77-c6): /proc/driver/nvidia/version does not exist
2021-06-07 10:36:15.378499: I tensorflow/compiler/jit/xla_gpu_device.cc:99] Not creating XLA devices, tf_xla_enable_xla_devices not set
Traceback (most recent call last):
  File "hf_modelV2.py", line 251, in <module>
    optimize_hf(Te=465.)
  File "hf_modelV2.py", line 229, in optimize_hf
    res = minimize(objective_function,bounds[i][0],tol=0.001,args=(ratio[i]*Total_hf,X[-1],T_list))
  File "/home/wesley/anaconda3/lib/python3.8/site-packages/scipy/optimize/_minimize.py", line 612, in minimize
    return _minimize_bfgs(fun, x0, args, jac, callback, **options)
  File "/home/wesley/anaconda3/lib/python3.8/site-packages/scipy/optimize/optimize.py", line 1101, in _minimize_bfgs
    sf = _prepare_scalar_function(fun, x0, jac, args=args, epsilon=eps,
  File "/home/wesley/anaconda3/lib/python3.8/site-packages/scipy/optimize/optimize.py", line 261, in _prepare_scalar_function
    sf = ScalarFunction(fun, x0, args, grad, hess,
  File "/home/wesley/anaconda3/lib/python3.8/site-packages/scipy/optimize/_differentiable_functions.py", line 76, in __init__
    self._update_fun()
  File "/home/wesley/anaconda3/lib/python3.8/site-packages/scipy/optimize/_differentiable_functions.py", line 166, in _update_fun
    self._update_fun_impl()
  File "/home/wesley/anaconda3/lib/python3.8/site-packages/scipy/optimize/_differentiable_functions.py", line 73, in update_fun
    self.f = fun_wrapped(self.x)
  File "/home/wesley/anaconda3/lib/python3.8/site-packages/scipy/optimize/_differentiable_functions.py", line 70, in fun_wrapped
    return fun(x, *args)
  File "hf_modelV2.py", line 35, in objective_function
    rescaled_X_predict = scaler.transform(x_predict[:, :-1])
  File "/home/wesley/anaconda3/lib/python3.8/site-packages/sklearn/preprocessing/_data.py", line 791, in transform
    X = self._validate_data(X, reset=False,
  File "/home/wesley/anaconda3/lib/python3.8/site-packages/sklearn/base.py", line 436, in _validate_data
    self._check_n_features(X, reset=reset)
  File "/home/wesley/anaconda3/lib/python3.8/site-packages/sklearn/base.py", line 377, in _check_n_features
    raise ValueError(
ValueError: X has 35 features, but this StandardScaler is expecting 33 features as input.
Job Ended at Mon Jun  7 10:36:15 CST 2021
=======================================================
